Traceback (most recent call last):
  File "/usr/share/miniconda/envs/tutorial/lib/python3.8/site-packages/jupyter_cache/executors/utils.py", line 51, in single_nb_execution
    executenb(
  File "/usr/share/miniconda/envs/tutorial/lib/python3.8/site-packages/nbclient/client.py", line 1204, in execute
    return NotebookClient(nb=nb, resources=resources, km=km, **kwargs).execute()
  File "/usr/share/miniconda/envs/tutorial/lib/python3.8/site-packages/nbclient/util.py", line 84, in wrapped
    return just_run(coro(*args, **kwargs))
  File "/usr/share/miniconda/envs/tutorial/lib/python3.8/site-packages/nbclient/util.py", line 62, in just_run
    return loop.run_until_complete(coro)
  File "/usr/share/miniconda/envs/tutorial/lib/python3.8/asyncio/base_events.py", line 616, in run_until_complete
    return future.result()
  File "/usr/share/miniconda/envs/tutorial/lib/python3.8/site-packages/nbclient/client.py", line 663, in async_execute
    await self.async_execute_cell(
  File "/usr/share/miniconda/envs/tutorial/lib/python3.8/site-packages/nbclient/client.py", line 965, in async_execute_cell
    await self._check_raise_for_error(cell, cell_index, exec_reply)
  File "/usr/share/miniconda/envs/tutorial/lib/python3.8/site-packages/nbclient/client.py", line 862, in _check_raise_for_error
    raise CellExecutionError.from_cell_and_msg(cell, exec_reply_content)
nbclient.exceptions.CellExecutionError: An error occurred while executing the following cell:
------------------
class Linear(nn.Module):
    def __init__(self):
        super().__init__()
        self.lin = nn.Linear(784, 10)

    def forward(self, xb):
        return self.lin(xb)
------------------

[0;31m---------------------------------------------------------------------------[0m
[0;31mNameError[0m                                 Traceback (most recent call last)
Cell [0;32mIn [10], line 1[0m
[0;32m----> 1[0m [38;5;28;01mclass[39;00m [38;5;21;01mLinear[39;00m(nn[38;5;241m.[39mModule):
[1;32m      2[0m     [38;5;28;01mdef[39;00m [38;5;21m__init__[39m([38;5;28mself[39m):
[1;32m      3[0m         [38;5;28msuper[39m()[38;5;241m.[39m[38;5;21m__init__[39m()

[0;31mNameError[0m: name 'nn' is not defined
NameError: name 'nn' is not defined

